<?xml version="1.0" encoding="UTF-8"?>
<!-- Generated by org.testng.reporters.JUnitReportReporter -->
<testsuite hostname="King" name="TestCases.P2P_DR_Mobile_SeriesA" tests="21" failures="0" timestamp="30 Sep 2017 10:29:33 GMT" time="636.841" errors="2">
  <testcase name="case3" time="21.744" classname="TestCases.P2P_DR_Mobile_SeriesA"/>
  <testcase name="case_17" time="2.502" classname="TestCases.P2P_DR_Mobile_SeriesA"/>
  <testcase name="case2" time="1.744" classname="TestCases.P2P_DR_Mobile_SeriesA"/>
  <testcase name="case6" time="22.210" classname="TestCases.P2P_DR_Mobile_SeriesA"/>
  <testcase name="case_10" time="41.502" classname="TestCases.P2P_DR_Mobile_SeriesA"/>
  <testcase name="case_13" time="2.001" classname="TestCases.P2P_DR_Mobile_SeriesA"/>
  <testcase name="case_19" time="2.150" classname="TestCases.P2P_DR_Mobile_SeriesA"/>
  <testcase name="case_14" time="2.112" classname="TestCases.P2P_DR_Mobile_SeriesA"/>
  <testcase name="case8" time="199.631" classname="TestCases.P2P_DR_Mobile_SeriesA"/>
  <testcase name="case4" time="38.177" classname="TestCases.P2P_DR_Mobile_SeriesA"/>
  <testcase name="case_11" time="20.384" classname="TestCases.P2P_DR_Mobile_SeriesA"/>
  <testcase name="Precondition" time="0.610" classname="TestCases.P2P_DR_Mobile_SeriesA"/>
  <testcase name="case_16" time="10.616" classname="TestCases.P2P_DR_Mobile_SeriesA"/>
  <testcase name="case_20" time="22.797" classname="TestCases.P2P_DR_Mobile_SeriesA"/>
  <testcase name="case7" time="77.084" classname="TestCases.P2P_DR_Mobile_SeriesA"/>
  <testcase name="case_12" time="12.397" classname="TestCases.P2P_DR_Mobile_SeriesA"/>
  <testcase name="case_18" time="6.823" classname="TestCases.P2P_DR_Mobile_SeriesA">
    <error type="java.lang.reflect.InvocationTargetException">
      <![CDATA[java.lang.reflect.InvocationTargetException
	at sun.reflect.GeneratedMethodAccessor23.invoke(Unknown Source)
	at sun.reflect.DelegatingMethodAccessorImpl.invoke(DelegatingMethodAccessorImpl.java:43)
	at java.lang.reflect.Method.invoke(Method.java:498)
	at com.dafycredit.giveu.test.service.RunUnit_Service.runCase(RunUnit_Service.java:99)
	at TestCases.P2P_DR_Mobile_SeriesA.case_18(P2P_DR_Mobile_SeriesA.java:132)
	at sun.reflect.NativeMethodAccessorImpl.invoke0(Native Method)
	at sun.reflect.NativeMethodAccessorImpl.invoke(NativeMethodAccessorImpl.java:62)
	at sun.reflect.DelegatingMethodAccessorImpl.invoke(DelegatingMethodAccessorImpl.java:43)
	at java.lang.reflect.Method.invoke(Method.java:498)
	at org.testng.internal.MethodInvocationHelper.invokeMethod(MethodInvocationHelper.java:86)
	at org.testng.internal.InvokeMethodRunnable.runOne(InvokeMethodRunnable.java:54)
	at org.testng.internal.InvokeMethodRunnable.run(InvokeMethodRunnable.java:44)
	at java.util.concurrent.Executors$RunnableAdapter.call(Executors.java:511)
	at java.util.concurrent.FutureTask.run(FutureTask.java:266)
	at java.util.concurrent.ThreadPoolExecutor.runWorker(ThreadPoolExecutor.java:1142)
	at java.util.concurrent.ThreadPoolExecutor$Worker.run(ThreadPoolExecutor.java:617)
	at java.lang.Thread.run(Thread.java:745)
Caused by: java.lang.AssertionError: 未发现审核通过的合同或合同状态未改变(实际结果和预期结果不一致)  Actual 【时雪多】  but found 【时雪】
	at org.testng.Assert.fail(Assert.java:94)
	at com.dafycredit.giveu.test.handler.CheckAction_Handler.checkEquals(CheckAction_Handler.java:103)
	at com.dafycredit.giveu.test.handler.CheckAction_Handler.check(CheckAction_Handler.java:40)
	... 17 more
]]>
    </error>
  </testcase> <!-- case_18 -->
  <testcase name="case5" time="4.528" classname="TestCases.P2P_DR_Mobile_SeriesA"/>
  <testcase name="case9" time="111.841" classname="TestCases.P2P_DR_Mobile_SeriesA"/>
  <testcase name="case_15" time="32.330" classname="TestCases.P2P_DR_Mobile_SeriesA"/>
  <testcase name="case1" time="3.658" classname="TestCases.P2P_DR_Mobile_SeriesA">
    <error type="java.lang.reflect.InvocationTargetException">
      <![CDATA[java.lang.reflect.InvocationTargetException
	at sun.reflect.NativeMethodAccessorImpl.invoke0(Native Method)
	at sun.reflect.NativeMethodAccessorImpl.invoke(NativeMethodAccessorImpl.java:62)
	at sun.reflect.DelegatingMethodAccessorImpl.invoke(DelegatingMethodAccessorImpl.java:43)
	at java.lang.reflect.Method.invoke(Method.java:498)
	at com.dafycredit.giveu.test.service.RunUnit_Service.runCase(RunUnit_Service.java:99)
	at TestCases.P2P_DR_Mobile_SeriesA.case1(P2P_DR_Mobile_SeriesA.java:30)
	at sun.reflect.NativeMethodAccessorImpl.invoke0(Native Method)
	at sun.reflect.NativeMethodAccessorImpl.invoke(NativeMethodAccessorImpl.java:62)
	at sun.reflect.DelegatingMethodAccessorImpl.invoke(DelegatingMethodAccessorImpl.java:43)
	at java.lang.reflect.Method.invoke(Method.java:498)
	at org.testng.internal.MethodInvocationHelper.invokeMethod(MethodInvocationHelper.java:86)
	at org.testng.internal.InvokeMethodRunnable.runOne(InvokeMethodRunnable.java:54)
	at org.testng.internal.InvokeMethodRunnable.run(InvokeMethodRunnable.java:44)
	at java.util.concurrent.Executors$RunnableAdapter.call(Executors.java:511)
	at java.util.concurrent.FutureTask.run(FutureTask.java:266)
	at java.util.concurrent.ThreadPoolExecutor.runWorker(ThreadPoolExecutor.java:1142)
	at java.util.concurrent.ThreadPoolExecutor$Worker.run(ThreadPoolExecutor.java:617)
	at java.lang.Thread.run(Thread.java:745)
Caused by: java.lang.AssertionError: 安装启动失败(实际结果和预期结果不一致)  Actual 【开始体验】  but found 【开始体验1】
	at org.testng.Assert.fail(Assert.java:94)
	at com.dafycredit.giveu.test.handler.CheckAction_Handler.checkEquals(CheckAction_Handler.java:103)
	at com.dafycredit.giveu.test.handler.CheckAction_Handler.check(CheckAction_Handler.java:40)
	... 18 more
]]>
    </error>
  </testcase> <!-- case1 -->
</testsuite> <!-- TestCases.P2P_DR_Mobile_SeriesA -->
